Workbook
Name Slicer_Customer_name: #N/A
Name Slicer_Delivery_Status: #N/A
Name Slicer_Employee_Name: #N/A
Name Slicer_Product_Availability: #N/A
Name Slicer_productName: #N/A
Name Slicer_shipper_name: #N/A
Name Slicer_year_quarter: #N/A

Sheet Pivot Table
A3: Row Labels | B3: Sum of unit price
A4: On Time | B4: 0.96835982
A5: Pending | B5: 0.020046771
A6: Late | B6: 0.01159341
A7: Grand Total | B7: 1
A25: Row Labels | B25: Sum of Sales
A26: Available | B26: 0.85385373
A27: Not Available | B27: 0.14614627
A28: Grand Total | B28: 1
A38: Row Labels | B38: Sum of Sales
A39: Côte de Blaye | B39: 141396.73
A40: Thüringer Rostbratwurst | B40: 80368.672
A41: Raclette Courdavault | B41: 71155.7
A42: Tarte au sucre | B42: 47234.97
A43: Camembert Pierrot | B43: 46825.48
A44: Gnocchi di nonna Alice | B44: 42593.06
A45: Manjimup Dried Apples | B45: 41819.65
A46: Alice Mutton | B46: 32698.38
A47: Carnarvon Tigers | B47: 29171.875
A48: Rössle Sauerkraut | B48: 25696.64
A49: Mozzarella di Giovanni | B49: 24900.13
A50: Ipoh Coffee | B50: 23526.7
... A116: Grand Total | B116: 1265793
A120: Row Labels | B120: Sum of Sales
A121: 2015-Q1 | B121: 298491.55
A122: 2014-Q4 | B122: 181681.46
A123: 2014-Q3 | B123: 153937.77
A124: 2014-Q2 | B124: 143177.04
A125: 2015-Q2 | B125: 142132.31
A126: 2014-Q1 | B126: 138288.93
A127: 2013-Q4 | B127: 128355.4
A128: 2013-Q3 | B128: 79728.57
A129: Grand Total | B129: 1265793
A134: Row Labels | B134: Sum of total with freight
A135: United Package | B135: 561792.48
A136: Federal Shipping | B136: 403917.98
A137: Speedy Express | B137: 365025.27
A138: Grand Total | B138: 1330735.7
A142: Row Labels | B142: Sum of Sales
A143: QUICK-Stop | B143: 110277.31
...

Sheet Dashboard
G2: NORTHWIND SALES

Sheet orders
A1: orderID | B1: CustomerID | C1: EmployeeID | D1: Employee Name | E1: OrderDate | F1: RequiredDate | G1: ShippedDate | H1: Days to ship | I1: shipperID | J1: freight | K1: Sales | L1: Discount | M1: total with freight | N1: quantity | O1: Customer name | P1: shipper name | Q1: year | R1: month | S1: Quarter | T1: year-quarter | U1: Delivery Status | V1: unit price
A2: 10248 | B2: VINET | C2: 5 | D2: =_xlfn.XLOOKUP(Table1[[#This Row],[EmployeeID]],Table4[employeeID],Table4[employeeName]) -> Steven Buchanan | E2: 41459 | F2: 41487 | G2: 41471 | H2: =IF(Table1[[#This Row],[ShippedDate]]="","",IF(Table1[[#This Row],[OrderDate]]="","",Table1[[#This Row],[ShippedDate]]-Table1[[#This Row],[OrderDate]])) -> 12 | I2: 3 | J2: 32.38 | K2: =SUMIF(order_details!A:A,Table1[[#This Row],[orderID]],order_details!F:F) -> 440 | L2: =_xlfn.XLOOKUP(Table1[[#This Row],[orderID]],Table3[orderID],Table3[discount]) -> 0 | M2: =SUM(Table1[[#This Row],[Sales]],Table1[[#This Row],[freight]]) -> 472.38 | N2: =_xlfn.XLOOKUP(Table1[[#This Row],[orderID]],Table3[orderID],Table3[quantity]) -> 12 | O2: =_xlfn.XLOOKUP(Table1[[#This Row],[CustomerID]],customers!A:A,customers!B:B) -> Vins et alcools Chevalier | P2: =_xlfn.XLOOKUP(Table1[[#This Row],[shipperID]],Table6[shipperID],Table6[companyName]) -> Federal Shipping | Q2: =YEAR(Table1[[#This Row],[OrderDate]]) -> 2013 | R2: =MONTH(Table1[[#This Row],[OrderDate]]) -> 7 | S2: ="Q"&ROUNDUP(Table1[[#This Row],[month]]/3,0) -> Q3 | T2: =CONCATENATE(Table1[[#This Row],[year]],"-",Table1[[#This Row],[Quarter]]) -> 2013-Q3 | U2: =IF(H1="","Pending",IF(Table1[[#This Row],[Days to ship]]<Table1[[#This Row],[RequiredDate]],"On Time","Late")) -> On Time | V2: =_xlfn.XLOOKUP(Table1[[#This Row],[orderID]],Table3[orderID],Table3[unitPrice]) -> 14
A3: 10249 | B3: TOMSP | C3: 6 | D3: =_xlfn.XLOOKUP(Table1[[#This Row],[EmployeeID]],Table4[employeeID],Table4[employeeName]) -> Michael Suyama | E3: 41460 | F3: 41502 | G3: 41465 | H3: =IF(Table1[[#This Row],[ShippedDate]]="","",IF(Table1[[#This Row],[OrderDate]]="","",Table1[[#This Row],[ShippedDate]]-Table1[[#This Row],[OrderDate]])) -> 5 | I3: 1 | J3: 11.61 | K3: =SUMIF(order_details!A:A,Table1[[#This Row],[orderID]],order_details!F:F) -> 1863.4 | L3: =_xlfn.XLOOKUP(Table1[[#This Row],[orderID]],Table3[orderID],Table3[discount]) -> 0 | M3: =SUM(Table1[[#This Row],[Sales]],Table1[[#This Row],[freight]]) -> 1875.01 | N3: =_xlfn.XLOOKUP(Table1[[#This Row],[orderID]],Table3[orderID],Table3[quantity]) -> 9 | O3: =_xlfn.XLOOKUP(Table1[[#This Row],[CustomerID]],customers!A:A,customers!B:B) -> Toms Spezialitäten | P3: =_xlfn.XLOOKUP(Table1[[#This Row],[shipperID]],Table6[shipperID],Table6[companyName]) -> Speedy Express | Q3: =YEAR(Table1[[#This Row],[OrderDate]]) -> 2013 | R3: =MONTH(Table1[[#This Row],[OrderDate]]) -> 7 | S3: ="Q"&ROUNDUP(Table1[[#This Row],[month]]/3,0) -> Q3 | T3: =CONCATENATE(Table1[[#This Row],[year]],"-",Table1[[#This Row],[Quarter]]) -> 2013-Q3 | U3: =IF(H2="","Pending",IF(Table1[[#This Row],[Days to ship]]<Table1[[#This Row],[RequiredDate]],"On Time","Late")) -> On Time | V3: =_xlfn.XLOOKUP(Table1[[#This Row],[orderID]],Table3[orderID],Table3[unitPrice]) -> 18.6
A4: 10250 | B4: HANAR | C4: 4 | D4: =_xlfn.XLOOKUP(Table1[[#This Row],[EmployeeID]],Table4[employeeID],Table4[employeeName]) -> Margaret Peacock | E4: 41463 | F4: 41491 | G4: 41467 | H4: =IF(Table1[[#This Row],[ShippedDate]]="","",IF(Table1[[#This Row],[OrderDate]]="","",Table1[[#This Row],[ShippedDate]]-Table1[[#This Row],[OrderDate]])) -> 4 | I4: 2 | J4: 65.83 | K4: =SUMIF(order_details!A:A,Table1[[#This Row],[orderID]],order_details!F:F) -> 1552.6 | L4: =_xlfn.XLOOKUP(Table1[[#This Row],[orderID]],Table3[orderID],Table3[discount]) -> 0 | M4: =SUM(Table1[[#This Row],[Sales]],Table1[[#This Row],[freight]]) -> 1618.43 | N4: =_xlfn.XLOOKUP(Table1[[#This Row],[orderID]],Table3[orderID],Table3[quantity]) -> 10 | O4: =_xlfn.XLOOKUP(Table1[[#This Row],[CustomerID]],customers!A:A,customers!B:B) -> Hanari Carnes | P4: =_xlfn.XLOOKUP(Table1[[#This Row],[shipperID]],Table6[shipperID],Table6[companyName]) -> United Package | Q4: =YEAR(Table1[[#This Row],[OrderDate]]) -> 2013 | R4: =MONTH(Table1[[#This Row],[OrderDate]]) -> 7 | S4: ="Q"&ROUNDUP(Table1[[#This Row],[month]]/3,0) -> Q3 | T4: =CONCATENATE(Table1[[#This Row],[year]],"-",Table1[[#This Row],[Quarter]]) -> 2013-Q3 | U4: =IF(H3="","Pending",IF(Table1[[#This Row],[Days to ship]]<Table1[[#This Row],[RequiredDate]],"On Time","Late")) -> On Time | V4: =_xlfn.XLOOKUP(Table1[[#This Row],[orderID]],Table3[orderID],Table3[unitPrice]) -> 7.7
A5: 10251 | B5: VICTE | C5: 3 | D5: =_xlfn.XLOOKUP(Table1[[#This Row],[EmployeeID]],Table4[employeeID],Table4[employeeName]) -> Janet Leverling | E5: 41463 | F5: 41491 | G5: 41470 | H5: =IF(Table1[[#This Row],[ShippedDate]]="","",IF(Table1[[#This Row],[OrderDate]]="","",Table1[[#This Row],[ShippedDate]]-Table1[[#This Row],[OrderDate]])) -> 7 | I5: 1 | J5: 41.34 | K5: =SUMIF(order_details!A:A,Table1[[#This Row],[orderID]],order_details!F:F) -> 654.06 | L5: =_xlfn.XLOOKUP(Table1[[#This Row],[orderID]],Table3[orderID],Table3[discount]) -> 0.05 | M5: =SUM(Table1[[#This Row],[Sales]],Table1[[#This Row],[freight]]) -> 695.4 | N5: =_xlfn.XLOOKUP(Table1[[#This Row],[orderID]],Table3[orderID],Table3[quantity]) -> 6 | O5: =_xlfn.XLOOKUP(Table1[[#This Row],[CustomerID]],customers!A:A,customers!B:B) -> Victuailles en stock | P5: =_xlfn.XLOOKUP(Table1[[#This Row],[shipperID]],Table6[shipperID],Table6[companyName]) -> Speedy Express | Q5: =YEAR(Table1[[#This Row],[OrderDate]]) -> 2013 | R5: =MONTH(Table1[[#This Row],[OrderDate]]) -> 7 | S5: ="Q"&ROUNDUP(Table1[[#This Row],[month]]/3,0) -> Q3 | T5: =CONCATENATE(Table1[[#This Row],[year]],"-",Table1[[#This Row],[Quarter]]) -> 2013-Q3 | U5: =IF(H4="","Pending",IF(Table1[[#This Row],[Days to ship]]<Table1[[#This Row],[RequiredDate]],"On Time","Late")) -> On Time | V5: =_xlfn.XLOOKUP(Table1[[#This Row],[orderID]],Table3[orderID],Table3[unitPrice]) -> 16.8
A6: 10252 | B6: SUPRD | C6: 4 | D6: =_xlfn.XLOOKUP(Table1[[#This Row],[EmployeeID]],Table4[employeeID],Table4[employeeName]) -> Margaret Peacock | E6: 41464 | F6: 41492 | G6: 41466 | H6: =IF(Table1[[#This Row],[ShippedDate]]="","",IF(Table1[[#This Row],[OrderDate]]="","",Table1[[#This Row],[ShippedDate]]-Table1[[#This Row],[OrderDate]])) -> 2 | I6: 2 | J6: 51.3 | K6: =SUMIF(order_details!A:A,Table1[[#This Row],[orderID]],order_details!F:F) -> 3597.9 | L6: =_xlfn.XLOOKUP(Table1[[#This Row],[orderID]],Table3[orderID],Table3[discount]) -> 0.05 | M6: =SUM(Table1[[#This Row],[Sales]],Table1[[#This Row],[freight]]) -> 3649.2 | N6: =_xlfn.XLOOKUP(Table1[[#This Row],[orderID]],Table3[orderID],Table3[quantity]) -> 40 | O6: =_xlfn.XLOOKUP(Table1[[#This Row],[CustomerID]],customers!A:A,customers!B:B) -> Suprêmes délices | P6: =_xlfn.XLOOKUP(Table1[[#This Row],[shipperID]],Table6[shipperID],Table6[companyName]) -> United Package | Q6: =YEAR(Table1[[#This Row],[OrderDate]]) -> 2013 | R6: =MONTH(Table1[[#This Row],[OrderDate]]) -> 7 | S6: ="Q"&ROUNDUP(Table1[[#This Row],[month]]/3,0) -> Q3 | T6: =CONCATENATE(Table1[[#This Row],[year]],"-",Table1[[#This Row],[Quarter]]) -> 2013-Q3 | U6: =IF(H5="","Pending",IF(Table1[[#This Row],[Days to ship]]<Table1[[#This Row],[RequiredDate]],"On Time","Late")) -> On Time | V6: =_xlfn.XLOOKUP(Table1[[#This Row],[orderID]],Table3[orderID],Table3[unitPrice]) -> 64.8
A7: 10253 | B7: HANAR | C7: 3 | D7: =_xlfn.XLOOKUP(Table1[[#This Row],[EmployeeID]],Table4[employeeID],Table4[employeeName]) -> Janet Leverling | E7: 41465 | F7: 41479 | G7: 41471 | H7: =IF(Table1[[#This Row],[ShippedDate]]="","",IF(Table1[[#This Row],[OrderDate]]="","",Table1[[#This Row],[ShippedDate]]-Table1[[#This Row],[OrderDate]])) -> 6 | I7: 2 | J7: 58.17 | K7: =SUMIF(order_details!A:A,Table1[[#This Row],[orderID]],order_details!F:F) -> 1444.8 | L7: =_xlfn.XLOOKUP(Table1[[#This Row],[orderID]],Table3[orderID],Table3[discount]) -> 0 | M7: =SUM(Table1[[#This Row],[Sales]],Table1[[#This Row],[freight]]) -> 1502.97 | N7: =_xlfn.XLOOKUP(Table1[[#This Row],[orderID]],Table3[orderID],Table3[quantity]) -> 20 | O7: =_xlfn.XLOOKUP(Table1[[#This Row],[CustomerID]],customers!A:A,customers!B:B) -> Hanari Carnes | P7: =_xlfn.XLOOKUP(Table1[[#This Row],[shipperID]],Table6[shipperID],Table6[companyName]) -> United Package | Q7: =YEAR(Table1[[#This Row],[OrderDate]]) -> 2013 | R7: =MONTH(Table1[[#This Row],[OrderDate]]) -> 7 | S7: ="Q"&ROUNDUP(Table1[[#This Row],[month]]/3,0) -> Q3 | T7: =CONCATENATE(Table1[[#This Row],[year]],"-",Table1[[#This Row],[Quarter]]) -> 2013-Q3 | U7: =IF(H6="","Pending",IF(Table1[[#This Row],[Days to ship]]<Table1[[#This Row],[RequiredDate]],"On Time","Late")) -> On Time | V7: =_xlfn.XLOOKUP(Table1[[#This Row],[orderID]],Table3[orderID],Table3[unitPrice]) -> 10
A8: 10254 | B8: CHOPS | C8: 5 | D8: =_xlfn.XLOOKUP(Table1[[#This Row],[EmployeeID]],Table4[employeeID],Table4[employeeName]) -> Steven Buchanan | E8: 41466 | F8: 41494 | G8: 41478 | H8: =IF(Table1[[#This Row],[ShippedDate]]="","",IF(Table1[[#This Row],[OrderDate]]="","",Table1[[#This Row],[ShippedDate]]-Table1[[#This Row],[OrderDate]])) -> 12 | I8: 2 | J8: 22.98 | K8: =SUMIF(order_details!A:A,Table1[[#This Row],[orderID]],order_details!F:F) -> 556.62 | L8: =_xlfn.XLOOKUP(Table1[[#This Row],[orderID]],Table3[orderID],Table3[discount]) -> 0.15 | M8: =SUM(Table1[[#This Row],[Sales]],Table1[[#This Row],[freight]]) -> 579.6 | N8: =_xlfn.XLOOKUP(Table1[[#This Row],[orderID]],Table3[orderID],Table3[quantity]) -> 15 | O8: =_xlfn.XLOOKUP(Table1[[#This Row],[CustomerID]],customers!A:A,customers!B:B) -> Chop-suey Chinese | P8: =_xlfn.XLOOKUP(Table1[[#This Row],[shipperID]],Table6[shipperID],Table6[companyName]) -> United Package | Q8: =YEAR(Table1[[#This Row],[OrderDate]]) -> 2013 | R8: =MONTH(Table1[[#This Row],[OrderDate]]) -> 7 | S8: ="Q"&ROUNDUP(Table1[[#This Row],[month]]/3,0) -> Q3 | T8: =CONCATENATE(Table1[[#This Row],[year]],"-",Table1[[#This Row],[Quarter]]) -> 2013-Q3 | U8: =IF(H7="","Pending",IF(Table1[[#This Row],[Days to ship]]<Table1[[#This Row],[RequiredDate]],"On Time","Late")) -> On Time | V8: =_xlfn.XLOOKUP(Table1[[#This Row],[orderID]],Table3[orderID],Table3[unitPrice]) -> 3.6
A9: 10255 | B9: RICSU | C9: 9 | D9: =_xlfn.XLOOKUP(Table1[[#This Row],[EmployeeID]],Table4[employeeID],Table4[employeeName]) -> Anne Dodsworth | E9: 41467 | F9: 41495 | G9: 41470 | H9: =IF(Table1[[#This Row],[ShippedDate]]="","",IF(Table1[[#This Row],[OrderDate]]="","",Table1[[#This Row],[ShippedDate]]-Table1[[#This Row],[OrderDate]])) -> 3 | I9: 3 | J9: 148.33 | K9: =SUMIF(order_details!A:A,Table1[[#This Row],[orderID]],order_details!F:F) -> 2490.5 | L9: =_xlfn.XLOOKUP(Table1[[#This Row],[orderID]],Table3[orderID],Table3[discount]) -> 0 | M9: =SUM(Table1[[#This Row],[Sales]],Table1[[#This Row],[freight]]) -> 2638.83 | N9: =_xlfn.XLOOKUP(Table1[[#This Row],[orderID]],Table3[orderID],Table3[quantity]) -> 20 | O9: =_xlfn.XLOOKUP(Table1[[#This Row],[CustomerID]],customers!A:A,customers!B:B) -> Richter Supermarkt | P9: =_xlfn.XLOOKUP(Table1[[#This Row],[shipperID]],Table6[shipperID],Table6[companyName]) -> Federal Shipping | Q9: =YEAR(Table1[[#This Row],[OrderDate]]) -> 2013 | R9: =MONTH(Table1[[#This Row],[OrderDate]]) -> 7 | S9: ="Q"&ROUNDUP(Table1[[#This Row],[month]]/3,0) -> Q3 | T9: =CONCATENATE(Table1[[#This Row],[year]],"-",Table1[[#This Row],[Quarter]]) -> 2013-Q3 | U9: =IF(H8="","Pending",IF(Table1[[#This Row],[Days to ship]]<Table1[[#This Row],[RequiredDate]],"On Time","Late")) -> On Time | V9: =_xlfn.XLOOKUP(Table1[[#This Row],[orderID]],Table3[orderID],Table3[unitPrice]) -> 15.2
A10: 10256 | B10: WELLI | C10: 3 | D10: =_xlfn.XLOOKUP(Table1[[#This Row],[EmployeeID]],Table4[employeeID],Table4[employeeName]) -> Janet Leverling | E10: 41470 | F10: 41498 | G10: 41472 | H10: =IF(Table1[[#This Row],[ShippedDate]]="","",IF(Table1[[#This Row],[OrderDate]]="","",Table1[[#This Row],[ShippedDate]]-Table1[[#This Row],[OrderDate]])) -> 2 | I10: 2 | J10: 13.97 | K10: =SUMIF(order_details!A:A,Table1[[#This Row],[orderID]],order_details!F:F) -> 517.8 | L10: =_xlfn.XLOOKUP(Table1[[#This Row],[orderID]],Table3[orderID],Table3[discount]) -> 0 | M10: =SUM(Table1[[#This Row],[Sales]],Table1[[#This Row],[freight]]) -> 531.77 | N10: =_xlfn.XLOOKUP(Table1[[#This Row],[orderID]],Table3[orderID],Table3[quantity]) -> 15 | O10: =_xlfn.XLOOKUP(Table1[[#This Row],[CustomerID]],customers!A:A,customers!B:B) -> Wellington Importadora | P10: =_xlfn.XLOOKUP(Table1[[#This Row],[shipperID]],Table6[shipperID],Table6[companyName]) -> United Package | Q10: =YEAR(Table1[[#This Row],[OrderDate]]) -> 2013 | R10: =MONTH(Table1[[#This Row],[OrderDate]]) -> 7 | S10: ="Q"&ROUNDUP(Table1[[#This Row],[month]]/3,0) -> Q3 | T10: =CONCATENATE(Table1[[#This Row],[year]],"-",Table1[[#This Row],[Quarter]]) -> 2013-Q3 | U10: =IF(H9="","Pending",IF(Table1[[#This Row],[Days to ship]]<Table1[[#This Row],[RequiredDate]],"On Time","Late")) -> On Time | V10: =_xlfn.XLOOKUP(Table1[[#This Row],[orderID]],Table3[orderID],Table3[unitPrice]) -> 26.2
A11: 10257 | B11: HILAA | C11: 4 | D11: =_xlfn.XLOOKUP(Table1[[#This Row],[EmployeeID]],Table4[employeeID],Table4[employeeName]) -> Margaret Peacock | E11: 41471 | F11: 41499 | G11: 41477 | H11: =IF(Table1[[#This Row],[ShippedDate]]="","",IF(Table1[[#This Row],[OrderDate]]="","",Table1[[#This Row],[ShippedDate]]-Table1[[#This Row],[OrderDate]])) -> 6 | I11: 3 | J11: 81.91 | K11: =SUMIF(order_details!A:A,Table1[[#This Row],[orderID]],order_details!F:F) -> 1119.9 | L11: =_xlfn.XLOOKUP(Table1[[#This Row],[orderID]],Table3[orderID],Table3[discount]) -> 0 | M11: =SUM(Table1[[#This Row],[Sales]],Table1[[#This Row],[freight]]) -> 1201.81 | N11: =_xlfn.XLOOKUP(Table1[[#This Row],[orderID]],Table3[orderID],Table3[quantity]) -> 25 | O11: =_xlfn.XLOOKUP(Table1[[#This Row],[CustomerID]],customers!A:A,customers!B:B) -> HILARION-Abastos | P11: =_xlfn.XLOOKUP(Table1[[#This Row],[shipperID]],Table6[shipperID],Table6[companyName]) -> Federal Shipping | Q11: =YEAR(Table1[[#This Row],[OrderDate]]) -> 2013 | R11: =MONTH(Table1[[#This Row],[OrderDate]]) -> 7 | S11: ="Q"&ROUNDUP(Table1[[#This Row],[month]]/3,0) -> Q3 | T11: =CONCATENATE(Table1[[#This Row],[year]],"-",Table1[[#This Row],[Quarter]]) -> 2013-Q3 | U11: =IF(H10="","Pending",IF(Table1[[#This Row],[Days to ship]]<Table1[[#This Row],[RequiredDate]],"On Time","Late")) -> On Time | V11: =_xlfn.XLOOKUP(Table1[[#This Row],[orderID]],Table3[orderID],Table3[unitPrice]) -> 35.1
A12: 10258 | B12: ERNSH | C12: 1 | D12: =_xlfn.XLOOKUP(Table1[[#This Row],[EmployeeID]],Table4[employeeID],Table4[employeeName]) -> Nancy Davolio | E12: 41472 | F12: 41500 | G12: 41478 | H12: =IF(Table1[[#This Row],[ShippedDate]]="","",IF(Table1[[#This Row],[OrderDate]]="","",Table1[[#This Row],[ShippedDate]]-Table1[[#This Row],[OrderDate]])) -> 6 | I12: 1 | J12: 140.51 | K12: =SUMIF(order_details!A:A,Table1[[#This Row],[orderID]],order_details!F:F) -> 1614.88 | L12: =_xlfn.XLOOKUP(Table1[[#This Row],[orderID]],Table3[orderID],Table3[discount]) -> 0.2 | M12: =SUM(Table1[[#This Row],[Sales]],Table1[[#This Row],[freight]]) -> 1755.39 | N12: =_xlfn.XLOOKUP(Table1[[#This Row],[orderID]],Table3[orderID],Table3[quantity]) -> 50 | O12: =_xlfn.XLOOKUP(Table1[[#This Row],[CustomerID]],customers!A:A,customers!B:B) -> Ernst Handel | P12: =_xlfn.XLOOKUP(Table1[[#This Row],[shipperID]],Table6[shipperID],Table6[companyName]) -> Speedy Express | Q12: =YEAR(Table1[[#This Row],[OrderDate]]) -> 2013 | R12: =MONTH(Table1[[#This Row],[OrderDate]]) -> 7 | S12: ="Q"&ROUNDUP(Table1[[#This Row],[month]]/3,0) -> Q3 | T12: =CONCATENATE(Table1[[#This Row],[year]],"-",Table1[[#This Row],[Quarter]]) -> 2013-Q3 | U12: =IF(H11="","Pending",IF(Table1[[#This Row],[Days to ship]]<Table1[[#This Row],[RequiredDate]],"On Time","Late")) -> On Time | V12: =_xlfn.XLOOKUP(Table1[[#This Row],[orderID]],Table3[orderID],Table3[unitPrice]) -> 15.2
A13: 10259 | B13: CENTC | C13: 4 | D13: =_xlfn.XLOOKUP(Table1[[#This Row],[EmployeeID]],Table4[employeeID],Table4[employeeName]) -> Margaret Peacock | E13: 41473 | F13: 41501 | G13: 41480 | H13: =IF(Table1[[#This Row],[ShippedDate]]="","",IF(Table1[[#This Row],[OrderDate]]="","",Table1[[#This Row],[ShippedDate]]-Table1[[#This Row],[OrderDate]])) -> 7 | I13: 3 | J13: 3.25 | K13: =SUMIF(order_details!A:A,Table1[[#This Row],[orderID]],order_details!F:F) -> 100.8 | L13: =_xlfn.XLOOKUP(Table1[[#This Row],[orderID]],Table3[orderID],Table3[discount]) -> 0 | M13: =SUM(Table1[[#This Row],[Sales]],Table1[[#This Row],[freight]]) -> 104.05 | N13: =_xlfn.XLOOKUP(Table1[[#This Row],[orderID]],Table3[orderID],Table3[quantity]) -> 10 | O13: =_xlfn.XLOOKUP(Table1[[#This Row],[CustomerID]],customers!A:A,customers!B:B) -> Centro comercial Moctezuma | P13: =_xlfn.XLOOKUP(Table1[[#This Row],[shipperID]],Table6[shipperID],Table6[companyName]) -> Federal Shipping | Q13: =YEAR(Table1[[#This Row],[OrderDate]]) -> 2013 | R13: =MONTH(Table1[[#This Row],[OrderDate]]) -> 7 | S13: ="Q"&ROUNDUP(Table1[[#This Row],[month]]/3,0) -> Q3 | T13: =CONCATENATE(Table1[[#This Row],[year]],"-",Table1[[#This Row],[Quarter]]) -> 2013-Q3 | U13: =IF(H12="","Pending",IF(Table1[[#This Row],[Days to ship]]<Table1[[#This Row],[RequiredDate]],"On Time","Late")) -> On Time | V13: =_xlfn.XLOOKUP(Table1[[#This Row],[orderID]],Table3[orderID],Table3[unitPrice]) -> 8
... A761: 11007 | B761: PRINI | C761: 8 | D761: =_xlfn.XLOOKUP(Table1[[#This Row],[EmployeeID]],Table4[employeeID],Table4[employeeName]) -> Laura Callahan | E761: 42102 | F761: 42130 | G761: 42107 | H761: =IF(Table1[[#This Row],[ShippedDate]]="","",IF(Table1[[#This Row],[OrderDate]]="","",Table1[[#This Row],[ShippedDate]]-Table1[[#This Row],[OrderDate]])) -> 5 | I761: 2 | J761: 202.24 | K761: =SUMIF(order_details!A:A,Table1[[#This Row],[orderID]],order_details!F:F) -> 2633.9 | L761: =_xlfn.XLOOKUP(Table1[[#This Row],[orderID]],Table3[orderID],Table3[discount]) -> 0 | M761: =SUM(Table1[[#This Row],[Sales]],Table1[[#This Row],[freight]]) -> 2836.14 | N761: =_xlfn.XLOOKUP(Table1[[#This Row],[orderID]],Table3[orderID],Table3[quantity]) -> 30 | O761: =_xlfn.XLOOKUP(Table1[[#This Row],[CustomerID]],customers!A:A,customers!B:B) -> Princesa Isabel Vinhos | P761: =_xlfn.XLOOKUP(Table1[[#This Row],[shipperID]],Table6[shipperID],Table6[companyName]) -> United Package | Q761: =YEAR(Table1[[#This Row],[OrderDate]]) -> 2015 | R761: =MONTH(Table1[[#This Row],[OrderDate]]) -> 4 | S761: ="Q"&ROUNDUP(Table1[[#This Row],[month]]/3,0) -> Q2 | T761: =CONCATENATE(Table1[[#This Row],[year]],"-",Table1[[#This Row],[Quarter]]) -> 2015-Q2 | U761: =IF(H760="","Pending",IF(Table1[[#This Row],[Days to ship]]<Table1[[#This Row],[RequiredDate]],"On Time","Late")) -> On Time | V761: =_xlfn.XLOOKUP(Table1[[#This Row],[orderID]],Table3[orderID],Table3[unitPrice]) -> 40
A762: 11008 | B762: ERNSH | C762: 7 | D762: =_xlfn.XLOOKUP(Table1[[#This Row],[EmployeeID]],Table4[employeeID],Table4[employeeName]) -> Robert King | E762: 42102 | F762: 42130 | H762: =IF(Table1[[#This Row],[ShippedDate]]="","",IF(Table1[[#This Row],[OrderDate]]="","",Table1[[#This Row],[ShippedDate]]-Table1[[#This Row],[OrderDate]])) | I762: 3 | J762: 79.46 | K762: =SUMIF(order_details!A:A,Table1[[#This Row],[orderID]],order_details!F:F) -> 4680.9 | L762: =_xlfn.XLOOKUP(Table1[[#This Row],[orderID]],Table3[orderID],Table3[discount]) -> 0.05 | M762: =SUM(Table1[[#This Row],[Sales]],Table1[[#This Row],[freight]]) -> 4760.36 | N762: =_xlfn.XLOOKUP(Table1[[#This Row],[orderID]],Table3[orderID],Table3[quantity]) -> 70 | O762: =_xlfn.XLOOKUP(Table1[[#This Row],[CustomerID]],customers!A:A,customers!B:B) -> Ernst Handel | P762: =_xlfn.XLOOKUP(Table1[[#This Row],[shipperID]],Table6[shipperID],Table6[companyName]) -> Federal Shipping | Q762: =YEAR(Table1[[#This Row],[OrderDate]]) -> 2015 | R762: =MONTH(Table1[[#This Row],[OrderDate]]) -> 4 | S762: ="Q"&ROUNDUP(Table1[[#This Row],[month]]/3,0) -> Q2 | T762: =CONCATENATE(Table1[[#This Row],[year]],"-",Table1[[#This Row],[Quarter]]) -> 2015-Q2 | U762: =IF(H761="","Pending",IF(Table1[[#This Row],[Days to ship]]<Table1[[#This Row],[RequiredDate]],"On Time","Late")) -> Late | V762: =_xlfn.XLOOKUP(Table1[[#This Row],[orderID]],Table3[orderID],Table3[unitPrice]) -> 45.6
A763: 11009 | B763: GODOS | C763: 2 | D763: =_xlfn.XLOOKUP(Table1[[#This Row],[EmployeeID]],Table4[employeeID],Table4[employeeName]) -> Andrew Fuller | E763: 42102 | F763: 42130 | G763: 42104 | H763: =IF(Table1[[#This Row],[ShippedDate]]="","",IF(Table1[[#This Row],[OrderDate]]="","",Table1[[#This Row],[ShippedDate]]-Table1[[#This Row],[OrderDate]])) -> 2 | I763: 1 | J763: 59.11 | K763: =SUMIF(order_details!A:A,Table1[[#This Row],[orderID]],order_details!F:F) -> 616.5 | L763: =_xlfn.XLOOKUP(Table1[[#This Row],[orderID]],Table3[orderID],Table3[discount]) -> 0 | M763: =SUM(Table1[[#This Row],[Sales]],Table1[[#This Row],[freight]]) -> 675.61 | N763: =_xlfn.XLOOKUP(Table1[[#This Row],[orderID]],Table3[orderID],Table3[quantity]) -> 12 | O763: =_xlfn.XLOOKUP(Table1[[#This Row],[CustomerID]],customers!A:A,customers!B:B) -> Godos Cocina Típica | P763: =_xlfn.XLOOKUP(Table1[[#This Row],[shipperID]],Table6[shipperID],Table6[companyName]) -> Speedy Express | Q763: =YEAR(Table1[[#This Row],[OrderDate]]) -> 2015 | R763: =MONTH(Table1[[#This Row],[OrderDate]]) -> 4 | S763: ="Q"&ROUNDUP(Table1[[#This Row],[month]]/3,0) -> Q2 | T763: =CONCATENATE(Table1[[#This Row],[year]],"-",Table1[[#This Row],[Quarter]]) -> 2015-Q2 | U763: =IF(H762="","Pending",IF(Table1[[#This Row],[Days to ship]]<Table1[[#This Row],[RequiredDate]],"On Time","Late")) -> Pending | V763: =_xlfn.XLOOKUP(Table1[[#This Row],[orderID]],Table3[orderID],Table3[unitPrice]) -> 4.5
A764: 11010 | B764: REGGC | C764: 2 | D764: =_xlfn.XLOOKUP(Table1[[#This Row],[EmployeeID]],Table4[employeeID],Table4[employeeName]) -> Andrew Fuller | E764: 42103 | F764: 42131 | G764: 42115 | H764: =IF(Table1[[#This Row],[ShippedDate]]="","",IF(Table1[[#This Row],[OrderDate]]="","",Table1[[#This Row],[ShippedDate]]-Table1[[#This Row],[OrderDate]])) -> 12 | I764: 2 | J764: 28.71 | K764: =SUMIF(order_details!A:A,Table1[[#This Row],[orderID]],order_details!F:F) -> 645 | L764: =_xlfn.XLOOKUP(Table1[[#This Row],[orderID]],Table3[orderID],Table3[discount]) -> 0 | M764: =SUM(Table1[[#This Row],[Sales]],Table1[[#This Row],[freight]]) -> 673.71 | N764: =_xlfn.XLOOKUP(Table1[[#This Row],[orderID]],Table3[orderID],Table3[quantity]) -> 20 | O764: =_xlfn.XLOOKUP(Table1[[#This Row],[CustomerID]],customers!A:A,customers!B:B) -> Reggiani Caseifici | P764: =_xlfn.XLOOKUP(Table1[[#This Row],[shipperID]],Table6[shipperID],Table6[companyName]) -> United Package | Q764: =YEAR(Table1[[#This Row],[OrderDate]]) -> 2015 | R764: =MONTH(Table1[[#This Row],[OrderDate]]) -> 4 | S764: ="Q"&ROUNDUP(Table1[[#This Row],[month]]/3,0) -> Q2 | T764: =CONCATENATE(Table1[[#This Row],[year]],"-",Table1[[#This Row],[Quarter]]) -> 2015-Q2 | U764: =IF(H763="","Pending",IF(Table1[[#This Row],[Days to ship]]<Table1[[#This Row],[RequiredDate]],"On Time","Late")) -> On Time | V764: =_xlfn.XLOOKUP(Table1[[#This Row],[orderID]],Table3[orderID],Table3[unitPrice]) -> 30
A765: 11011 | B765: ALFKI | C765: 3 | D765: =_xlfn.XLOOKUP(Table1[[#This Row],[EmployeeID]],Table4[employeeID],Table4[employeeName]) -> Janet Leverling | E765: 42103 | F765: 42131 | G765: 42107 | H765: =IF(Table1[[#This Row],[ShippedDate]]="","",IF(Table1[[#This Row],[OrderDate]]="","",Table1[[#This Row],[ShippedDate]]-Table1[[#This Row],[OrderDate]])) -> 4 | I765: 1 | J765: 1.21 | K765: =SUMIF(order_details!A:A,Table1[[#This Row],[orderID]],order_details!F:F) -> 933.5 | L765: =_xlfn.XLOOKUP(Table1[[#This Row],[orderID]],Table3[orderID],Table3[discount]) -> 0.05 | M765: =SUM(Table1[[#This Row],[Sales]],Table1[[#This Row],[freight]]) -> 934.71 | N765: =_xlfn.XLOOKUP(Table1[[#This Row],[orderID]],Table3[orderID],Table3[quantity]) -> 40 | O765: =_xlfn.XLOOKUP(Table1[[#This Row],[CustomerID]],customers!A:A,customers!B:B) -> Alfreds Futterkiste | P765: =_xlfn.XLOOKUP(Table1[[#This Row],[shipperID]],Table6[shipperID],Table6[companyName]) -> Speedy Express | Q765: =YEAR(Table1[[#This Row],[OrderDate]]) -> 2015 | R765: =MONTH(Table1[[#This Row],[OrderDate]]) -> 4 | S765: ="Q"&ROUNDUP(Table1[[#This Row],[month]]/3,0) -> Q2 | T765: =CONCATENATE(Table1[[#This Row],[year]],"-",Table1[[#This Row],[Quarter]]) -> 2015-Q2 | U765: =IF(H764="","Pending",IF(Table1[[#This Row],[Days to ship]]<Table1[[#This Row],[RequiredDate]],"On Time","Late")) -> On Time | V765: =_xlfn.XLOOKUP(Table1[[#This Row],[orderID]],Table3[orderID],Table3[unitPrice]) -> 13.25
A766: 11012 | B766: FRANK | C766: 1 | D766: =_xlfn.XLOOKUP(Table1[[#This Row],[EmployeeID]],Table4[employeeID],Table4[employeeName]) -> Nancy Davolio | E766: 42103 | F766: 42117 | G766: 42111 | H766: =IF(Table1[[#This Row],[ShippedDate]]="","",IF(Table1[[#This Row],[OrderDate]]="","",Table1[[#This Row],[ShippedDate]]-Table1[[#This Row],[OrderDate]])) -> 8 | I766: 3 | J766: 242.95 | K766: =SUMIF(order_details!A:A,Table1[[#This Row],[orderID]],order_details!F:F) -> 2825.3 | L766: =_xlfn.XLOOKUP(Table1[[#This Row],[orderID]],Table3[orderID],Table3[discount]) -> 0.05 | M766: =SUM(Table1[[#This Row],[Sales]],Table1[[#This Row],[freight]]) -> 3068.25 | N766: =_xlfn.XLOOKUP(Table1[[#This Row],[orderID]],Table3[orderID],Table3[quantity]) -> 50 | O766: =_xlfn.XLOOKUP(Table1[[#This Row],[CustomerID]],customers!A:A,customers!B:B) -> Frankenversand | P766: =_xlfn.XLOOKUP(Table1[[#This Row],[shipperID]],Table6[shipperID],Table6[companyName]) -> Federal Shipping | Q766: =YEAR(Table1[[#This Row],[OrderDate]]) -> 2015 | R766: =MONTH(Table1[[#This Row],[OrderDate]]) -> 4 | S766: ="Q"&ROUNDUP(Table1[[#This Row],[month]]/3,0) -> Q2 | T766: =CONCATENATE(Table1[[#This Row],[year]],"-",Table1[[#This Row],[Quarter]]) -> 2015-Q2 | U766: =IF(H765="","Pending",IF(Table1[[#This Row],[Days to ship]]<Table1[[#This Row],[RequiredDate]],"On Time","Late")) -> On Time | V766: =_xlfn.XLOOKUP(Table1[[#This Row],[orderID]],Table3[orderID],Table3[unitPrice]) -> 9.2
A767: 11013 | B767: ROMEY | C767: 2 | D767: =_xlfn.XLOOKUP(Table1[[#This Row],[EmployeeID]],Table4[employeeID],Table4[employeeName]) -> Andrew Fuller | E767: 42103 | F767: 42131 | G767: 42104 | H767: =IF(Table1[[#This Row],[ShippedDate]]="","",IF(Table1[[#This Row],[OrderDate]]="","",Table1[[#This Row],[ShippedDate]]-Table1[[#This Row],[OrderDate]])) -> 1 | I767: 1 | J767: 32.99 | K767: =SUMIF(order_details!A:A,Table1[[#This Row],[orderID]],order_details!F:F) -> 361 | L767: =_xlfn.XLOOKUP(Table1[[#This Row],[orderID]],Table3[orderID],Table3[discount]) -> 0 | M767: =SUM(Table1[[#This Row],[Sales]],Table1[[#This Row],[freight]]) -> 393.99 | N767: =_xlfn.XLOOKUP(Table1[[#This Row],[orderID]],Table3[orderID],Table3[quantity]) -> 10 | O767: =_xlfn.XLOOKUP(Table1[[#This Row],[CustomerID]],customers!A:A,customers!B:B) -> Romero y tomillo | P767: =_xlfn.XLOOKUP(Table1[[#This Row],[shipperID]],Table6[shipperID],Table6[companyName]) -> Speedy Express | Q767: =YEAR(Table1[[#This Row],[OrderDate]]) -> 2015 | R767: =MONTH(Table1[[#This Row],[OrderDate]]) -> 4 | S767: ="Q"&ROUNDUP(Table1[[#This Row],[month]]/3,0) -> Q2 | T767: =CONCATENATE(Table1[[#This Row],[year]],"-",Table1[[#This Row],[Quarter]]) -> 2015-Q2 | U767: =IF(H766="","Pending",IF(Table1[[#This Row],[Days to ship]]<Table1[[#This Row],[RequiredDate]],"On Time","Late")) -> On Time | V767: =_xlfn.XLOOKUP(Table1[[#This Row],[orderID]],Table3[orderID],Table3[unitPrice]) -> 9
A768: 11014 | B768: LINOD | C768: 2 | D768: =_xlfn.XLOOKUP(Table1[[#This Row],[EmployeeID]],Table4[employeeID],Table4[employeeName]) -> Andrew Fuller | E768: 42104 | F768: 42132 | G768: 42109 | H768: =IF(Table1[[#This Row],[ShippedDate]]="","",IF(Table1[[#This Row],[OrderDate]]="","",Table1[[#This Row],[ShippedDate]]-Table1[[#This Row],[OrderDate]])) -> 5 | I768: 3 | J768: 23.6 | K768: =SUMIF(order_details!A:A,Table1[[#This Row],[orderID]],order_details!F:F) -> 243.18 | L768: =_xlfn.XLOOKUP(Table1[[#This Row],[orderID]],Table3[orderID],Table3[discount]) -> 0.1 | M768: =SUM(Table1[[#This Row],[Sales]],Table1[[#This Row],[freight]]) -> 266.78 | N768: =_xlfn.XLOOKUP(Table1[[#This Row],[orderID]],Table3[orderID],Table3[quantity]) -> 28 | O768: =_xlfn.XLOOKUP(Table1[[#This Row],[CustomerID]],customers!A:A,customers!B:B) -> LINO-Delicateses | P768: =_xlfn.XLOOKUP(Table1[[#This Row],[shipperID]],Table6[shipperID],Table6[companyName]) -> Federal Shipping | Q768: =YEAR(Table1[[#This Row],[OrderDate]]) -> 2015 | R768: =MONTH(Table1[[#This Row],[OrderDate]]) -> 4 | S768: ="Q"&ROUNDUP(Table1[[#This Row],[month]]/3,0) -> Q2 | T768: =CONCATENATE(Table1[[#This Row],[year]],"-",Table1[[#This Row],[Quarter]]) -> 2015-Q2 | U768: =IF(H767="","Pending",IF(Table1[[#This Row],[Days to ship]]<Table1[[#This Row],[RequiredDate]],"On Time","Late")) -> On Time | V768: =_xlfn.XLOOKUP(Table1[[#This Row],[orderID]],Table3[orderID],Table3[unitPrice]) -> 9.65
A769: 11015 | B769: SANTG | C769: 2 | D769: =_xlfn.XLOOKUP(Table1[[#This Row],[EmployeeID]],Table4[employeeID],Table4[employeeName]) -> Andrew Fuller | E769: 42104 | F769: 42118 | G769: 42114 | H769: =IF(Table1[[#This Row],[ShippedDate]]="","",IF(Table1[[#This Row],[OrderDate]]="","",Table1[[#This Row],[ShippedDate]]-Table1[[#This Row],[OrderDate]])) -> 10 | I769: 2 | J769: 4.62 | K769: =SUMIF(order_details!A:A,Table1[[#This Row],[orderID]],order_details!F:F) -> 622.35 | L769: =_xlfn.XLOOKUP(Table1[[#This Row],[orderID]],Table3[orderID],Table3[discount]) -> 0 | M769: =SUM(Table1[[#This Row],[Sales]],Table1[[#This Row],[freight]]) -> 626.97 | N769: =_xlfn.XLOOKUP(Table1[[#This Row],[orderID]],Table3[orderID],Table3[quantity]) -> 15 | O769: =_xlfn.XLOOKUP(Table1[[#This Row],[CustomerID]],customers!A:A,customers!B:B) -> Santé Gourmet | P769: =_xlfn.XLOOKUP(Table1[[#This Row],[shipperID]],Table6[shipperID],Table6[companyName]) -> United Package | Q769: =YEAR(Table1[[#This Row],[OrderDate]]) -> 2015 | R769: =MONTH(Table1[[#This Row],[OrderDate]]) -> 4 | S769: ="Q"&ROUNDUP(Table1[[#This Row],[month]]/3,0) -> Q2 | T769: =CONCATENATE(Table1[[#This Row],[year]],"-",Table1[[#This Row],[Quarter]]) -> 2015-Q2 | U769: =IF(H768="","Pending",IF(Table1[[#This Row],[Days to ship]]<Table1[[#This Row],[RequiredDate]],"On Time","Late")) -> On Time | V769: =_xlfn.XLOOKUP(Table1[[#This Row],[orderID]],Table3[orderID],Table3[unitPrice]) -> 25.89
A770: 11016 | B770: AROUT | C770: 9 | D770: =_xlfn.XLOOKUP(Table1[[#This Row],[EmployeeID]],Table4[employeeID],Table4[employeeName]) -> Anne Dodsworth | E770: 42104 | F770: 42132 | G770: 42107 | H770: =IF(Table1[[#This Row],[ShippedDate]]="","",IF(Table1[[#This Row],[OrderDate]]="","",Table1[[#This Row],[ShippedDate]]-Table1[[#This Row],[OrderDate]])) -> 3 | I770: 2 | J770: 33.8 | K770: =SUMIF(order_details!A:A,Table1[[#This Row],[orderID]],order_details!F:F) -> 491.5 | L770: =_xlfn.XLOOKUP(Table1[[#This Row],[orderID]],Table3[orderID],Table3[discount]) -> 0 | M770: =SUM(Table1[[#This Row],[Sales]],Table1[[#This Row],[freight]]) -> 525.3 | N770: =_xlfn.XLOOKUP(Table1[[#This Row],[orderID]],Table3[orderID],Table3[quantity]) -> 15 | O770: =_xlfn.XLOOKUP(Table1[[#This Row],[CustomerID]],customers!A:A,customers!B:B) -> Around the Horn | P770: =_xlfn.XLOOKUP(Table1[[#This Row],[shipperID]],Table6[shipperID],Table6[companyName]) -> United Package | Q770: =YEAR(Table1[[#This Row],[OrderDate]]) -> 2015 | R770: =MONTH(Table1[[#This Row],[OrderDate]]) -> 4 | S770: ="Q"&ROUNDUP(Table1[[#This Row],[month]]/3,0) -> Q2 | T770: =CONCATENATE(Table1[[#This Row],[year]],"-",Table1[[#This Row],[Quarter]]) -> 2015-Q2 | U770: =IF(H769="","Pending",IF(Table1[[#This Row],[Days to ship]]<Table1[[#This Row],[RequiredDate]],"On Time","Late")) -> On Time | V770: =_xlfn.XLOOKUP(Table1[[#This Row],[orderID]],Table3[orderID],Table3[unitPrice]) -> 12.5
A771: 11017 | B771: ERNSH | C771: 9 | D771: =_xlfn.XLOOKUP(Table1[[#This Row],[EmployeeID]],Table4[employeeID],Table4[employeeName]) -> Anne Dodsworth | E771: 42107 | F771: 42135 | G771: 42114 | H771: =IF(Table1[[#This Row],[ShippedDate]]="","",IF(Table1[[#This Row],[OrderDate]]="","",Table1[[#This Row],[ShippedDate]]-Table1[[#This Row],[OrderDate]])) -> 7 | I771: 2 | J771: 754.26 | K771: =SUMIF(order_details!A:A,Table1[[#This Row],[orderID]],order_details!F:F) -> 6750 | L771: =_xlfn.XLOOKUP(Table1[[#This Row],[orderID]],Table3[orderID],Table3[discount]) -> 0 | M771: =SUM(Table1[[#This Row],[Sales]],Table1[[#This Row],[freight]]) -> 7504.26 | N771: =_xlfn.XLOOKUP(Table1[[#This Row],[orderID]],Table3[orderID],Table3[quantity]) -> 25 | O771: =_xlfn.XLOOKUP(Table1[[#This Row],[CustomerID]],customers!A:A,customers!B:B) -> Ernst Handel | P771: =_xlfn.XLOOKUP(Table1[[#This Row],[shipperID]],Table6[shipperID],Table6[companyName]) -> United Package | Q771: =YEAR(Table1[[#This Row],[OrderDate]]) -> 2015 | R771: =MONTH(Table1[[#This Row],[OrderDate]]) -> 4 | S771: ="Q"&ROUNDUP(Table1[[#This Row],[month]]/3,0) -> Q2 | T771: =CONCATENATE(Table1[[#This Row],[year]],"-",Table1[[#This Row],[Quarter]]) -> 2015-Q2 | U771: =IF(H770="","Pending",IF(Table1[[#This Row],[Days to ship]]<Table1[[#This Row],[RequiredDate]],"On Time","Late")) -> On Time | V771: =_xlfn.XLOOKUP(Table1[[#This Row],[orderID]],Table3[orderID],Table3[unitPrice]) -> 10
A772: 11018 | B772: LONEP | C772: 4 | D772: =_xlfn.XLOOKUP(Table1[[#This Row],[EmployeeID]],Table4[employeeID],Table4[employeeName]) -> Margaret Peacock | E772: 42107 | F772: 42135 | G772: 42110 | H772: =IF(Table1[[#This Row],[ShippedDate]]="","",IF(Table1[[#This Row],[OrderDate]]="","",Table1[[#This Row],[ShippedDate]]-Table1[[#This Row],[OrderDate]])) -> 3 | I772: 2 | J772: 11.65 | K772: =SUMIF(order_details!A:A,Table1[[#This Row],[orderID]],order_details!F:F) -> 1575 | L772: =_xlfn.XLOOKUP(Table1[[#This Row],[orderID]],Table3[orderID],Table3[discount]) -> 0 | M772: =SUM(Table1[[#This Row],[Sales]],Table1[[#This Row],[freight]]) -> 1586.65 | N772: =_xlfn.XLOOKUP(Table1[[#This Row],[orderID]],Table3[orderID],Table3[quantity]) -> 20 | O772: =_xlfn.XLOOKUP(Table1[[#This Row],[CustomerID]],customers!A:A,customers!B:B) -> Lonesome Pine Restaurant | P772: =_xlfn.XLOOKUP(Table1[[#This Row],[shipperID]],Table6[shipperID],Table6[companyName]) -> United Package | Q772: =YEAR(Table1[[#This Row],[OrderDate]]) -> 2015 | R772: =MONTH(Table1[[#This Row],[OrderDate]]) -> 4 | S772: ="Q"&ROUNDUP(Table1[[#This Row],[month]]/3,0) -> Q2 | T772: =CONCATENATE(Table1[[#This Row],[year]],"-",Table1[[#This Row],[Quarter]]) -> 2015-Q2 | U772: =IF(H771="","Pending",IF(Table1[[#This Row],[Days to ship]]<Table1[[#This Row],[RequiredDate]],"On Time","Late")) -> On Time | V772: =_xlfn.XLOOKUP(Table1[[#This Row],[orderID]],Table3[orderID],Table3[unitPrice]) -> 38
A773: 11019 | B773: RANCH | C773: 6 | D773: =_xlfn.XLOOKUP(Table1[[#This Row],[EmployeeID]],Table4[employeeID],Table4[employeeName]) -> Michael Suyama | E773: 42107 | F773: 42135 | H773: =IF(Table1[[#This Row],[ShippedDate]]="","",IF(Table1[[#This Row],[OrderDate]]="","",Table1[[#This Row],[ShippedDate]]-Table1[[#This Row],[OrderDate]])) | I773: 3 | J773: 3.17 | K773: =SUMIF(order_details!A:A,Table1[[#This Row],[orderID]],order_details!F:F) -> 76 | L773: =_xlfn.XLOOKUP(Table1[[#This Row],[orderID]],Table3[orderID],Table3[discount]) -> 0 | M773: =SUM(Table1[[#This Row],[Sales]],Table1[[#This Row],[freight]]) -> 79.17 | N773: =_xlfn.XLOOKUP(Table1[[#This Row],[orderID]],Table3[orderID],Table3[quantity]) -> 3 | O773: =_xlfn.XLOOKUP(Table1[[#This Row],[CustomerID]],customers!A:A,customers!B:B) -> Rancho grande | P773: =_xlfn.XLOOKUP(Table1[[#This Row],[shipperID]],Table6[shipperID],Table6[companyName]) -> Federal Shipping | Q773: =YEAR(Table1[[#This Row],[OrderDate]]) -> 2015 | R773: =MONTH(Table1[[#This Row],[OrderDate]]) -> 4 | S773: ="Q"&ROUNDUP(Table1[[#This Row],[month]]/3,0) -> Q2 | T773: =CONCATENATE(Table1[[#This Row],[year]],"-",Table1[[#This Row],[Quarter]]) -> 2015-Q2 | U773: =IF(H772="","Pending",IF(Table1[[#This Row],[Days to ship]]<Table1[[#This Row],[RequiredDate]],"On Time","Late")) -> Late | V773: =_xlfn.XLOOKUP(Table1[[#This Row],[orderID]],Table3[orderID],Table3[unitPrice]) -> 12
A774: 11020 | B774: OTTIK | C774: 2 | D774: =_xlfn.XLOOKUP(Table1[[#This Row],[EmployeeID]],Table4[employeeID],Table4[employeeName]) -> Andrew Fuller | E774: 42108 | F774: 42136 | G774: 42110 | H774: =IF(Table1[[#This Row],[ShippedDate]]="","",IF(Table1[[#This Row],[OrderDate]]="","",Table1[[#This Row],[ShippedDate]]-Table1[[#This Row],[OrderDate]])) -> 2 | I774: 2 | J774: 43.3 | K774: =SUMIF(order_details!A:A,Table1[[#This Row],[orderID]],order_details!F:F) -> 632.4 | L774: =_xlfn.XLOOKUP(Table1[[#This Row],[orderID]],Table3[orderID],Table3[discount]) -> 0.15 | M774: =SUM(Table1[[#This Row],[Sales]],Table1[[#This Row],[freight]]) -> 675.7 | N774: =_xlfn.XLOOKUP(Table1[[#This Row],[orderID]],Table3[orderID],Table3[quantity]) -> 24 | O774: =_xlfn.XLOOKUP(Table1[[#This Row],[CustomerID]],customers!A:A,customers!B:B) -> Ottilies Käseladen | P774: =_xlfn.XLOOKUP(Table1[[#This Row],[shipperID]],Table6[shipperID],Table6[companyName]) -> United Package | Q774: =YEAR(Table1[[#This Row],[OrderDate]]) -> 2015 | R774: =MONTH(Table1[[#This Row],[OrderDate]]) -> 4 | S774: ="Q"&ROUNDUP(Table1[[#This Row],[month]]/3,0) -> Q2 | T774: =CONCATENATE(Table1[[#This Row],[year]],"-",Table1[[#This Row],[Quarter]]) -> 2015-Q2 | U774: =IF(H773="","Pending",IF(Table1[[#This Row],[Days to ship]]<Table1[[#This Row],[RequiredDate]],"On Time","Late")) -> Pending | V774: =_xlfn.XLOOKUP(Table1[[#This Row],[orderID]],Table3[orderID],Table3[unitPrice]) -> 31
A775: 11021 | B775: QUICK | C775: 3 | D775: =_xlfn.XLOOKUP(Table1[[#This Row],[EmployeeID]],Table4[employeeID],Table4[employeeName]) -> Janet Leverling | E775: 42108 | F775: 42136 | G775: 42115 | H775: =IF(Table1[[#This Row],[ShippedDate]]="","",IF(Table1[[#This Row],[OrderDate]]="","",Table1[[#This Row],[ShippedDate]]-Table1[[#This Row],[OrderDate]])) -> 7 | I775: 1 | J775: 297.18 | K775: =SUMIF(order_details!A:A,Table1[[#This Row],[orderID]],order_details!F:F) -> 6306.24 | L775: =_xlfn.XLOOKUP(Table1[[#This Row],[orderID]],Table3[orderID],Table3[discount]) -> 0.25 | M775: =SUM(Table1[[#This Row],[Sales]],Table1[[#This Row],[freight]]) -> 6603.42 | N775: =_xlfn.XLOOKUP(Table1[[#This Row],[orderID]],Table3[orderID],Table3[quantity]) -> 11 | O775: =_xlfn.XLOOKUP(Table1[[#This Row],[CustomerID]],customers!A:A,customers!B:B) -> QUICK-Stop | P775: =_xlfn.XLOOKUP(Table1[[#This Row],[shipperID]],Table6[shipperID],Table6[companyName]) -> Speedy Express | Q775: =YEAR(Table1[[#This Row],[OrderDate]]) -> 2015 | R775: =MONTH(Table1[[#This Row],[OrderDate]]) -> 4 | S775: ="Q"&ROUNDUP(Table1[[#This Row],[month]]/3,0) -> Q2 | T775: =CONCATENATE(Table1[[#This Row],[year]],"-",Table1[[#This Row],[Quarter]]) -> 2015-Q2 | U775: =IF(H774="","Pending",IF(Table1[[#This Row],[Days to ship]]<Table1[[#This Row],[RequiredDate]],"On Time","Late")) -> On Time | V775: =_xlfn.XLOOKUP(Table1[[#This Row],[orderID]],Table3[orderID],Table3[unitPrice]) -> 19
A776: 11022 | B776: HANAR | C776: 9 | D776: =_xlfn.XLOOKUP(Table1[[#This Row],[EmployeeID]],Table4[employeeID],Table4[employeeName]) -> Anne Dodsworth | E776: 42108 | F776: 42136 | G776: 42128 | H776: =IF(Table1[[#This Row],[ShippedDate]]="","",IF(Table1[[#This Row],[OrderDate]]="","",Table1[[#This Row],[ShippedDate]]-Table1[[#This Row],[OrderDate]])) -> 20 | I776: 2 | J776: 6.27 | K776: =SUMIF(order_details!A:A,Table1[[#This Row],[orderID]],order_details!F:F) -> 1402 | L776: =_xlfn.XLOOKUP(Table1[[#This Row],[orderID]],Table3[orderID],Table3[discount]) -> 0 | M776: =SUM(Table1[[#This Row],[Sales]],Table1[[#This Row],[freight]]) -> 1408.27 | N776: =_xlfn.XLOOKUP(Table1[[#This Row],[orderID]],Table3[orderID],Table3[quantity]) -> 35 | O776: =_xlfn.XLOOKUP(Table1[[#This Row],[CustomerID]],customers!A:A,customers!B:B) -> Hanari Carnes | P776: =_xlfn.XLOOKUP(Table1[[#This Row],[shipperID]],Table6[shipperID],Table6[companyName]) -> United Package | Q776: =YEAR(Table1[[#This Row],[OrderDate]]) -> 2015 | R776: =MONTH(Table1[[#This Row],[OrderDate]]) -> 4 | S776: ="Q"&ROUNDUP(Table1[[#This Row],[month]]/3,0) -> Q2 | T776: =CONCATENATE(Table1[[#This Row],[year]],"-",Table1[[#This Row],[Quarter]]) -> 2015-Q2 | U776: =IF(H775="","Pending",IF(Table1[[#This Row],[Days to ship]]<Table1[[#This Row],[RequiredDate]],"On Time","Late")) -> On Time | V776: =_xlfn.XLOOKUP(Table1[[#This Row],[orderID]],Table3[orderID],Table3[unitPrice]) -> 9.2
A777: 11023 | B777: BSBEV | C777: 1 | D777: =_xlfn.XLOOKUP(Table1[[#This Row],[EmployeeID]],Table4[employeeID],Table4[employeeName]) -> Nancy Davolio | E777: 42108 | F777: 42122 | G777: 42118 | H777: =IF(Table1[[#This Row],[ShippedDate]]="","",IF(Table1[[#This Row],[OrderDate]]="","",Table1[[#This Row],[ShippedDate]]-Table1[[#This Row],[OrderDate]])) -> 10 | I777: 2 | J777: 123.83 | K777: =SUMIF(order_details!A:A,Table1[[#This Row],[orderID]],order_details!F:F) -> 1500 | L777: =_xlfn.XLOOKUP(Table1[[#This Row],[orderID]],Table3[orderID],Table3[discount]) -> 0 | M777: =SUM(Table1[[#This Row],[Sales]],Table1[[#This Row],[freight]]) -> 1623.83 | N777: =_xlfn.XLOOKUP(Table1[[#This Row],[orderID]],Table3[orderID],Table3[quantity]) -> 4 | O777: =_xlfn.XLOOKUP(Table1[[#This Row],[CustomerID]],customers!A:A,customers!B:B) -> B's Beverages | P777: =_xlfn.XLOOKUP(Table1[[#This Row],[shipperID]],Table6[shipperID],Table6[companyName]) -> United Package | Q777: =YEAR(Table1[[#This Row],[OrderDate]]) -> 2015 | R777: =MONTH(Table1[[#This Row],[OrderDate]]) -> 4 | S777: ="Q"&ROUNDUP(Table1[[#This Row],[month]]/3,0) -> Q2 | T777: =CONCATENATE(Table1[[#This Row],[year]],"-",Table1[[#This Row],[Quarter]]) -> 2015-Q2 | U777: =IF(H776="","Pending",IF(Table1[[#This Row],[Days to ship]]<Table1[[#This Row],[RequiredDate]],"On Time","Late")) -> On Time | V777: =_xlfn.XLOOKUP(Table1[[#This Row],[orderID]],Table3[orderID],Table3[unitPrice]) -> 30
A778: 11024 | B778: EASTC | C778: 4 | D778: =_xlfn.XLOOKUP(Table1[[#This Row],[EmployeeID]],Table4[employeeID],Table4[employeeName]) -> Margaret Peacock | E778: 42109 | F778: 42137 | G778: 42114 | H778: =IF(Table1[[#This Row],[ShippedDate]]="","",IF(Table1[[#This Row],[OrderDate]]="","",Table1[[#This Row],[ShippedDate]]-Table1[[#This Row],[OrderDate]])) -> 5 | I778: 1 | J778: 74.36 | K778: =SUMIF(order_details!A:A,Table1[[#This Row],[orderID]],order_details!F:F) -> 1966.81 | L778: =_xlfn.XLOOKUP(Table1[[#This Row],[orderID]],Table3[orderID],Table3[discount]) -> 0 | M778: =SUM(Table1[[#This Row],[Sales]],Table1[[#This Row],[freight]]) -> 2041.17 | N778: =_xlfn.XLOOKUP(Table1[[#This Row],[orderID]],Table3[orderID],Table3[quantity]) -> 12 | O778: =_xlfn.XLOOKUP(Table1[[#This Row],[CustomerID]],customers!A:A,customers!B:B) -> Eastern Connection | P778: =_xlfn.XLOOKUP(Table1[[#This Row],[shipperID]],Table6[shipperID],Table6[companyName]) -> Speedy Express | Q778: =YEAR(Table1[[#This Row],[OrderDate]]) -> 2015 | R778: =MONTH(Table1[[#This Row],[OrderDate]]) -> 4 | S778: ="Q"&ROUNDUP(Table1[[#This Row],[month]]/3,0) -> Q2 | T778: =CONCATENATE(Table1[[#This Row],[year]],"-",Table1[[#This Row],[Quarter]]) -> 2015-Q2 | U778: =IF(H777="","Pending",IF(Table1[[#This Row],[Days to ship]]<Table1[[#This Row],[RequiredDate]],"On Time","Late")) -> On Time | V778: =_xlfn.XLOOKUP(Table1[[#This Row],[orderID]],Table3[orderID],Table3[unitPrice]) -> 31.23
A779: 11025 | B779: WARTH | C779: 6 | D779: =_xlfn.XLOOKUP(Table1[[#This Row],[EmployeeID]],Table4[employeeID],Table4[employeeName]) -> Michael Suyama | E779: 42109 | F779: 42137 | G779: 42118 | H779: =IF(Table1[[#This Row],[ShippedDate]]="","",IF(Table1[[#This Row],[OrderDate]]="","",Table1[[#This Row],[ShippedDate]]-Table1[[#This Row],[OrderDate]])) -> 9 | I779: 3 | J779: 29.17 | K779: =SUMIF(order_details!A:A,Table1[[#This Row],[orderID]],order_details!F:F) -> 270 | L779: =_xlfn.XLOOKUP(Table1[[#This Row],[orderID]],Table3[orderID],Table3[discount]) -> 0.1 | M779: =SUM(Table1[[#This Row],[Sales]],Table1[[#This Row],[freight]]) -> 299.17 | N779: =_xlfn.XLOOKUP(Table1[[#This Row],[orderID]],Table3[orderID],Table3[quantity]) -> 10 | O779: =_xlfn.XLOOKUP(Table1[[#This Row],[CustomerID]],customers!A:A,customers!B:B) -> Wartian Herkku | P779: =_xlfn.XLOOKUP(Table1[[#This Row],[shipperID]],Table6[shipperID],Table6[companyName]) -> Federal Shipping | Q779: =YEAR(Table1[[#This Row],[OrderDate]]) -> 2015 | R779: =MONTH(Table1[[#This Row],[OrderDate]]) -> 4 | S779: ="Q"&ROUNDUP(Table1[[#This Row],[month]]/3,0) -> Q2 | T779: =CONCATENATE(Table1[[#This Row],[year]],"-",Table1[[#This Row],[Quarter]]) -> 2015-Q2 | U779: =IF(H778="","Pending",IF(Table1[[#This Row],[Days to ship]]<Table1[[#This Row],[RequiredDate]],"On Time","Late")) -> On Time | V779: =_xlfn.XLOOKUP(Table1[[#This Row],[orderID]],Table3[orderID],Table3[unitPrice]) -> 18
A780: 11026 | B780: FRANS | C780: 4 | D780: =_xlfn.XLOOKUP(Table1[[#This Row],[EmployeeID]],Table4[employeeID],Table4[employeeName]) -> Margaret Peacock | E780: 42109 | F780: 42137 | G780: 42122 | H780: =IF(Table1[[#This Row],[ShippedDate]]="","",IF(Table1[[#This Row],[OrderDate]]="","",Table1[[#This Row],[ShippedDate]]-Table1[[#This Row],[OrderDate]])) -> 13 | I780: 1 | J780: 47.09 | K780: =SUMIF(order_details!A:A,Table1[[#This Row],[orderID]],order_details!F:F) -> 1030 | L780: =_xlfn.XLOOKUP(Table1[[#This Row],[orderID]],Table3[orderID],Table3[discount]) -> 0 | M780: =SUM(Table1[[#This Row],[Sales]],Table1[[#This Row],[freight]]) -> 1077.09 | N780: =_xlfn.XLOOKUP(Table1[[#This Row],[orderID]],Table3[orderID],Table3[quantity]) -> 8 | O780: =_xlfn.XLOOKUP(Table1[[#This Row],[CustomerID]],customers!A:A,customers!B:B) -> Franchi S.p.A. | P780: =_xlfn.XLOOKUP(Table1[[#This Row],[shipperID]],Table6[shipperID],Table6[companyName]) -> Speedy Express | Q780: =YEAR(Table1[[#This Row],[OrderDate]]) -> 2015 | R780: =MONTH(Table1[[#This Row],[OrderDate]]) -> 4 | S780: ="Q"&ROUNDUP(Table1[[#This Row],[month]]/3,0) -> Q2 | T780: =CONCATENATE(Table1[[#This Row],[year]],"-",Table1[[#This Row],[Quarter]]) -> 2015-Q2 | U780: =IF(H779="","Pending",IF(Table1[[#This Row],[Days to ship]]<Table1[[#This Row],[RequiredDate]],"On Time","Late")) -> On Time | V780: =_xlfn.XLOOKUP(Table1[[#This Row],[orderID]],Table3[orderID],Table3[unitPrice]) -> 62.5
A781: 11027 | B781: BOTTM | C781: 1 | D781: =_xlfn.XLOOKUP(Table1[[#This Row],[EmployeeID]],Table4[employeeID],Table4[employeeName]) -> Nancy Davolio | E781: 42110 | F781: 42138 | G781: 42114 | H781: =IF(Table1[[#This Row],[ShippedDate]]="","",IF(Table1[[#This Row],[OrderDate]]="","",Table1[[#This Row],[ShippedDate]]-Table1[[#This Row],[OrderDate]])) -> 4 | I781: 1 | J781: 52.52 | K781: =SUMIF(order_details!A:A,Table1[[#This Row],[orderID]],order_details!F:F) -> 877.725 | L781: =_xlfn.XLOOKUP(Table1[[#This Row],[orderID]],Table3[orderID],Table3[discount]) -> 0.25 | M781: =SUM(Table1[[#This Row],[Sales]],Table1[[#This Row],[freight]]) -> 930.245 | N781: =_xlfn.XLOOKUP(Table1[[#This Row],[orderID]],Table3[orderID],Table3[quantity]) -> 30 | O781: =_xlfn.XLOOKUP(Table1[[#This Row],[CustomerID]],customers!A:A,customers!B:B) -> Bottom-Dollar Markets | P781: =_xlfn.XLOOKUP(Table1[[#This Row],[shipperID]],Table6[shipperID],Table6[companyName]) -> Speedy Express | Q781: =YEAR(Table1[[#This Row],[OrderDate]]) -> 2015 | R781: =MONTH(Table1[[#This Row],[OrderDate]]) -> 4 | S781: ="Q"&ROUNDUP(Table1[[#This Row],[month]]/3,0) -> Q2 | T781: =CONCATENATE(Table1[[#This Row],[year]],"-",Table1[[#This Row],[Quarter]]) -> 2015-Q2 | U781: =IF(H780="","Pending",IF(Table1[[#This Row],[Days to ship]]<Table1[[#This Row],[RequiredDate]],"On Time","Late")) -> On Time | V781: =_xlfn.XLOOKUP(Table1[[#This Row],[orderID]],Table3[orderID],Table3[unitPrice]) -> 4.5
A782: 11028 | B782: KOENE | C782: 2 | D782: =_xlfn.XLOOKUP(Table1[[#This Row],[EmployeeID]],Table4[employeeID],Table4[employeeName]) -> Andrew Fuller | E782: 42110 | F782: 42138 | G782: 42116 | H782: =IF(Table1[[#This Row],[ShippedDate]]="","",IF(Table1[[#This Row],[OrderDate]]="","",Table1[[#This Row],[ShippedDate]]-Table1[[#This Row],[OrderDate]])) -> 6 | I782: 1 | J782: 29.59 | K782: =SUMIF(order_details!A:A,Table1[[#This Row],[orderID]],order_details!F:F) -> 2160 | L782: =_xlfn.XLOOKUP(Table1[[#This Row],[orderID]],Table3[orderID],Table3[discount]) -> 0 | M782: =SUM(Table1[[#This Row],[Sales]],Table1[[#This Row],[freight]]) -> 2189.59 | N782: =_xlfn.XLOOKUP(Table1[[#This Row],[orderID]],Table3[orderID],Table3[quantity]) -> 35 | O782: =_xlfn.XLOOKUP(Table1[[#This Row],[CustomerID]],customers!A:A,customers!B:B) -> Königlich Essen | P782: =_xlfn.XLOOKUP(Table1[[#This Row],[shipperID]],Table6[shipperID],Table6[companyName]) -> Speedy Express | Q782: =YEAR(Table1[[#This Row],[OrderDate]]) -> 2015 | R782: =MONTH(Table1[[#This Row],[OrderDate]]) -> 4 | S782: ="Q"&ROUNDUP(Table1[[#This Row],[month]]/3,0) -> Q2 | T782: =CONCATENATE(Table1[[#This Row],[year]],"-",Table1[[#This Row],[Quarter]]) -> 2015-Q2 | U782: =IF(H781="","Pending",IF(Table1[[#This Row],[Days to ship]]<Table1[[#This Row],[RequiredDate]],"On Time","Late")) -> On Time | V782: =_xlfn.XLOOKUP(Table1[[#This Row],[orderID]],Table3[orderID],Table3[unitPrice]) -> 24
A783: 11029 | B783: CHOPS | C783: 4 | D783: =_xlfn.XLOOKUP(Table1[[#This Row],[EmployeeID]],Table4[employeeID],Table4[employeeName]) -> Margaret Peacock | E783: 42110 | F783: 42138 | G783: 42121 | H783: =IF(Table1[[#This Row],[ShippedDate]]="","",IF(Table1[[#This Row],[OrderDate]]="","",Table1[[#This Row],[ShippedDate]]-Table1[[#This Row],[OrderDate]])) -> 11 | I783: 1 | J783: 47.84 | K783: =SUMIF(order_details!A:A,Table1[[#This Row],[orderID]],order_details!F:F) -> 1286.8 | L783: =_xlfn.XLOOKUP(Table1[[#This Row],[orderID]],Table3[orderID],Table3[discount]) -> 0 | M783: =SUM(Table1[[#This Row],[Sales]],Table1[[#This Row],[freight]]) -> 1334.64 | N783: =_xlfn.XLOOKUP(Table1[[#This Row],[orderID]],Table3[orderID],Table3[quantity]) -> 20 | O783: =_xlfn.XLOOKUP(Table1[[#This Row],[CustomerID]],customers!A:A,customers!B:B) -> Chop-suey Chinese | P783: =_xlfn.XLOOKUP(Table1[[#This Row],[shipperID]],Table6[shipperID],Table6[companyName]) -> Speedy Express | Q783: =YEAR(Table1[[#This Row],[OrderDate]]) -> 2015 | R783: =MONTH(Table1[[#This Row],[OrderDate]]) -> 4 | S783: ="Q"&ROUNDUP(Table1[[#This Row],[month]]/3,0) -> Q2 | T783: =CONCATENATE(Table1[[#This Row],[year]],"-",Table1[[#This Row],[Quarter]]) -> 2015-Q2 | U783: =IF(H782="","Pending",IF(Table1[[#This Row],[Days to ship]]<Table1[[#This Row],[RequiredDate]],"On Time","Late")) -> On Time | V783: =_xlfn.XLOOKUP(Table1[[#This Row],[orderID]],Table3[orderID],Table3[unitPrice]) -> 38
A784: 11030 | B784: SAVEA | C784: 7 | D784: =_xlfn.XLOOKUP(Table1[[#This Row],[EmployeeID]],Table4[employeeID],Table4[employeeName]) -> Robert King | E784: 42111 | F784: 42139 | G784: 42121 | H784: =IF(Table1[[#This Row],[ShippedDate]]="","",IF(Table1[[#This Row],[OrderDate]]="","",Table1[[#This Row],[ShippedDate]]-Table1[[#This Row],[OrderDate]])) -> 10 | I784: 2 | J784: 830.75 | K784: =SUMIF(order_details!A:A,Table1[[#This Row],[orderID]],order_details!F:F) -> 12615.05 | L784: =_xlfn.XLOOKUP(Table1[[#This Row],[orderID]],Table3[orderID],Table3[discount]) -> 0.25 | M784: =SUM(Table1[[#This Row],[Sales]],Table1[[#This Row],[freight]]) -> 13445.8 | N784: =_xlfn.XLOOKUP(Table1[[#This Row],[orderID]],Table3[orderID],Table3[quantity]) -> 100 | O784: =_xlfn.XLOOKUP(Table1[[#This Row],[CustomerID]],customers!A:A,customers!B:B) -> Save-a-lot Markets | P784: =_xlfn.XLOOKUP(Table1[[#This Row],[shipperID]],Table6[shipperID],Table6[companyName]) -> United Package | Q784: =YEAR(Table1[[#This Row],[OrderDate]]) -> 2015 | R784: =MONTH(Table1[[#This Row],[OrderDate]]) -> 4 | S784: ="Q"&ROUNDUP(Table1[[#This Row],[month]]/3,0) -> Q2 | T784: =CONCATENATE(Table1[[#This Row],[year]],"-",Table1[[#This Row],[Quarter]]) -> 2015-Q2 | U784: =IF(H783="","Pending",IF(Table1[[#This Row],[Days to ship]]<Table1[[#This Row],[RequiredDate]],"On Time","Late")) -> On Time | V784: =_xlfn.XLOOKUP(Table1[[#This Row],[orderID]],Table3[orderID],Table3[unitPrice]) -> 19
A785: 11031 | B785: SAVEA | C785: 6 | D785: =_xlfn.XLOOKUP(Table1[[#This Row],[EmployeeID]],Table4[employeeID],Table4[employeeName]) -> Michael Suyama | E785: 42111 | F785: 42139 | G785: 42118 | H785: =IF(Table1[[#This Row],[ShippedDate]]="","",IF(Table1[[#This Row],[OrderDate]]="","",Table1[[#This Row],[ShippedDate]]-Table1[[#This Row],[OrderDate]])) -> 7 | I785: 2 | J785: 227.22 | K785: =SUMIF(order_details!A:A,Table1[[#This Row],[orderID]],order_details!F:F) -> 2393.5 | L785: =_xlfn.XLOOKUP(Table1[[#This Row],[orderID]],Table3[orderID],Table3[discount]) -> 0 | M785: =SUM(Table1[[#This Row],[Sales]],Table1[[#This Row],[freight]]) -> 2620.72 | N785: =_xlfn.XLOOKUP(Table1[[#This Row],[orderID]],Table3[orderID],Table3[quantity]) -> 45 | O785: =_xlfn.XLOOKUP(Table1[[#This Row],[CustomerID]],customers!A:A,customers!B:B) -> Save-a-lot Markets | P785: =_xlfn.XLOOKUP(Table1[[#This Row],[shipperID]],Table6[shipperID],Table6[companyName]) -> United Package | Q785: =YEAR(Table1[[#This Row],[OrderDate]]) -> 2015 | R785: =MONTH(Table1[[#This Row],[OrderDate]]) -> 4 | S785: ="Q"&ROUNDUP(Table1[[#This Row],[month]]/3,0) -> Q2 | T785: =CONCATENATE(Table1[[#This Row],[year]],"-",Table1[[#This Row],[Quarter]]) -> 2015-Q2 | U785: =IF(H784="","Pending",IF(Table1[[#This Row],[Days to ship]]<Table1[[#This Row],[RequiredDate]],"On Time","Late")) -> On Time | V785: =_xlfn.XLOOKUP(Table1[[#This Row],[orderID]],Table3[orderID],Table3[unitPrice]) -> 18
... A792: 11038 | B792: SUPRD | C792: 1 | D792: =_xlfn.XLOOKUP(Table1[[#This Row],[EmployeeID]],Table4[employeeID],Table4[employeeName]) -> Nancy Davolio | E792: 42115 | F792: 42143 | G792: 42124 | H792: =IF(Table1[[#This Row],[ShippedDate]]="","",IF(Table1[[#This Row],[OrderDate]]="","",Table1[[#This Row],[ShippedDate]]-Table1[[#This Row],[OrderDate]])) -> 9 | I792: 2 | J792: 29.59 | K792: =SUMIF(order_details!A:A,Table1[[#This Row],[orderID]],order_details!F:F) -> 732.6 | L792: =_xlfn.XLOOKUP(Table1[[#This Row],[orderID]],Table3[orderID],Table3[discount]) -> 0.2 | M792: =SUM(Table1[[#This Row],[Sales]],Table1[[#This Row],[freight]]) -> 762.19 | N792: =_xlfn.XLOOKUP(Table1[[#This Row],[orderID]],Table3[orderID],Table3[quantity]) -> 5 | O792: =_xlfn.XLOOKUP(Table1[[#This Row],[CustomerID]],customers!A:A,customers!B:B) -> Suprêmes délices | P792: =_xlfn.XLOOKUP(Table1[[#This Row],[shipperID]],Table6[shipperID],Table6[companyName]) -> United Package | Q792: =YEAR(Table1[[#This Row],[OrderDate]]) -> 2015 | R792: =MONTH(Table1[[#This Row],[OrderDate]]) -> 4 | S792: ="Q"&ROUNDUP(Table1[[#This Row],[month]]/3,0) -> Q2 | T792: =CONCATENATE(Table1[[#This Row],[year]],"-",Table1[[#This Row],[Quarter]]) -> 2015-Q2 | U792: =IF(H791="","Pending",IF(Table1[[#This Row],[Days to ship]]<Table1[[#This Row],[RequiredDate]],"On Time","Late")) -> On Time | V792: =_xlfn.XLOOKUP(Table1[[#This Row],[orderID]],Table3[orderID],Table3[unitPrice]) -> 18.4
A793: 11039 | B793: LINOD | C793: 1 | D793: =_xlfn.XLOOKUP(Table1[[#This Row],[EmployeeID]],Table4[employeeID],Table4[employeeName]) -> Nancy Davolio | E793: 42115 | F793: 42143 | H793: =IF(Table1[[#This Row],[ShippedDate]]="","",IF(Table1[[#This Row],[OrderDate]]="","",Table1[[#This Row],[ShippedDate]]-Table1[[#This Row],[OrderDate]])) | I793: 2 | J793: 65 | K793: =SUMIF(order_details!A:A,Table1[[#This Row],[orderID]],order_details!F:F) -> 3090 | L793: =_xlfn.XLOOKUP(Table1[[#This Row],[orderID]],Table3[orderID],Table3[discount]) -> 0 | M793: =SUM(Table1[[#This Row],[Sales]],Table1[[#This Row],[freight]]) -> 3155 | N793: =_xlfn.XLOOKUP(Table1[[#This Row],[orderID]],Table3[orderID],Table3[quantity]) -> 20 | O793: =_xlfn.XLOOKUP(Table1[[#This Row],[CustomerID]],customers!A:A,customers!B:B) -> LINO-Delicateses | P793: =_xlfn.XLOOKUP(Table1[[#This Row],[shipperID]],Table6[shipperID],Table6[companyName]) -> United Package | Q793: =YEAR(Table1[[#This Row],[OrderDate]]) -> 2015 | R793: =MONTH(Table1[[#This Row],[OrderDate]]) -> 4 | S793: ="Q"&ROUNDUP(Table1[[#This Row],[month]]/3,0) -> Q2 | T793: =CONCATENATE(Table1[[#This Row],[year]],"-",Table1[[#This Row],[Quarter]]) -> 2015-Q2 | U793: =IF(H792="","Pending",IF(Table1[[#This Row],[Days to ship]]<Table1[[#This Row],[RequiredDate]],"On Time","Late")) -> Late | V793: =_xlfn.XLOOKUP(Table1[[#This Row],[orderID]],Table3[orderID],Table3[unitPrice]) -> 45.6
...

Sheet products
A1: productID | B1: productName | C1: quantityPerUnit | D1: unitPrice | E1: discontinued | F1: Product Availability | G1: categoryID | H1: Sales
A2: 1 | B2: Chai | C2: 10 boxes x 20 bags | D2: 18 | E2: 0 | F2: =IF(Table2[[#This Row],[discontinued]]=0,"Available"," Not Available") -> Available | G2: 1 | H2: =SUMIF(order_details!B:B,Table2[[#This Row],[productID]],order_details!F:F) -> 12788.1
A3: 2 | B3: Chang | C3: 24 - 12 oz bottles | D3: 19 | E3: 0 | F3: =IF(Table2[[#This Row],[discontinued]]=0,"Available"," Not Available") -> Available | G3: 1 | H3: =SUMIF(order_details!B:B,Table2[[#This Row],[productID]],order_details!F:F) -> 16355.96
A4: 3 | B4: Aniseed Syrup | C4: 12 - 550 ml bottles | D4: 10 | E4: 0 | F4: =IF(Table2[[#This Row],[discontinued]]=0,"Available"," Not Available") -> Available | G4: 2 | H4: =SUMIF(order_details!B:B,Table2[[#This Row],[productID]],order_details!F:F) -> 3044
A5: 4 | B5: Chef Anton's Cajun Seasoning | C5: 48 - 6 oz jars | D5: 22 | E5: 0 | F5: =IF(Table2[[#This Row],[discontinued]]=0,"Available"," Not Available") -> Available | G5: 2 | H5: =SUMIF(order_details!B:B,Table2[[#This Row],[productID]],order_details!F:F) -> 8567.9
A6: 5 | B6: Chef Anton's Gumbo Mix | C6: 36 boxes | D6: 21.35 | E6: 1 | F6: =IF(Table2[[#This Row],[discontinued]]=0,"Available"," Not Available") -> Not Available | G6: 2 | H6: =SUMIF(order_details!B:B,Table2[[#This Row],[productID]],order_details!F:F) -> 5347.2
A7: 6 | B7: Grandma's Boysenberry Spread | C7: 12 - 8 oz jars | D7: 25 | E7: 0 | F7: =IF(Table2[[#This Row],[discontinued]]=0,"Available"," Not Available") -> Available | G7: 2 | H7: =SUMIF(order_details!B:B,Table2[[#This Row],[productID]],order_details!F:F) -> 7137
